Workbook

Sheet APMMDB
A1: Task | B1: MU | C1: Node | D1: Session | E1: Uproc | F1: Start Date | G1: End Date | H1: Task-lookup_UAC | I1: Average Running Duration | J1: NOTE
A2: CASE_PACK_EXPORT | B2: PMMDB | C2: apmmdb | D2: CSP_EXPORT | E2: H_CSP_EXPORT | F2: 21/12/2025 19:59:05 | G2: 21/12/2025 19:59:07 | H2: =VLOOKUP(E2,UAC!A:A,1,FALSE) -> #N/A | I2: 31s
A3: CASE_PACK_EXPORT | B3: PMMDB | C3: apmmdb | D3: CSP_EXPORT | E3: H_CSP_EXPORT | F3: 22/12/2025 20:16:07 | G3: 22/12/2025 20:16:09 | H3: =VLOOKUP(E3,UAC!A:A,1,FALSE) -> #N/A
A4: CASE_PACK_EXPORT | B4: PMMDB | C4: apmmdb | D4: CSP_EXPORT | E4: JDA_PMM_CSP_EXPORT_CASEPACK | F4: 21/12/2025 19:59:08 | G4: 21/12/2025 19:59:16 | H4: =VLOOKUP(E4,UAC!A:A,1,FALSE) -> JDA_PMM_CSP_EXPORT_CASEPACK | I4: 6s
A5: CASE_PACK_EXPORT | B5: PMMDB | C5: apmmdb | D5: CSP_EXPORT | E5: JDA_PMM_CSP_EXPORT_CASEPACK | F5: 22/12/2025 20:16:09 | G5: 22/12/2025 20:16:19 | H5: =VLOOKUP(E5,UAC!A:A,1,FALSE) -> JDA_PMM_CSP_EXPORT_CASEPACK
A6: CASE_PACK_EXPORT | B6: PMMDB | C6: apmmdb | D6: CSP_EXPORT | E6: JDA_PMM_CSP_EXPORT_CASEPACK_AF | F6: 21/12/2025 19:59:08 | G6: 21/12/2025 19:59:37 | H6: =VLOOKUP(E6,UAC!A:A,1,FALSE) -> JDA_PMM_CSP_EXPORT_CASEPACK_AF | I6: 1s
A7: CASE_PACK_EXPORT | B7: PMMDB | C7: apmmdb | D7: CSP_EXPORT | E7: JDA_PMM_CSP_EXPORT_CASEPACK_AF | F7: 22/12/2025 20:16:09 | G7: 22/12/2025 20:16:37 | H7: =VLOOKUP(E7,UAC!A:A,1,FALSE) -> JDA_PMM_CSP_EXPORT_CASEPACK_AF
A8: CASE_PACK_EXPORT | B8: PMMDB | C8: apmmdb | D8: CSP_EXPORT | E8: JDA_PMM_CSP_EXPORT_CASEPACK_COST | F8: 21/12/2025 19:59:08 | G8: 21/12/2025 19:59:22 | H8: =VLOOKUP(E8,UAC!A:A,1,FALSE) -> JDA_PMM_CSP_EXPORT_CASEPACK_COST | I8: 13s
A9: CASE_PACK_EXPORT | B9: PMMDB | C9: apmmdb | D9: CSP_EXPORT | E9: JDA_PMM_CSP_EXPORT_CASEPACK_COST | F9: 22/12/2025 20:16:09 | G9: 22/12/2025 20:16:26 | H9: =VLOOKUP(E9,UAC!A:A,1,FALSE) -> JDA_PMM_CSP_EXPORT_CASEPACK_COST
A10: CASE_PACK_EXPORT | B10: PMMDB | C10: apmmdb | D10: CSP_EXPORT | E10: JDA_PMM_CSP_EXPORT_CASEPACK_FLAT | F10: 21/12/2025 19:59:38 | G10: 21/12/2025 19:59:56 | H10: =VLOOKUP(E10,UAC!A:A,1,FALSE) -> JDA_PMM_CSP_EXPORT_CASEPACK_FLAT | I10: 6s
A11: CASE_PACK_EXPORT | B11: PMMDB | C11: apmmdb | D11: CSP_EXPORT | E11: JDA_PMM_CSP_EXPORT_CASEPACK_FLAT | F11: 22/12/2025 20:16:37 | G11: 22/12/2025 20:17:04 | H11: =VLOOKUP(E11,UAC!A:A,1,FALSE) -> JDA_PMM_CSP_EXPORT_CASEPACK_FLAT
A12: CASE_PACK_EXPORT | B12: PMMDB | C12: apmmdb | D12: CSP_EXPORT | E12: JDA_PMM_CSP_REJECT_REP | F12: 21/12/2025 19:59:57 | G12: 21/12/2025 20:00:05 | H12: =VLOOKUP(E12,UAC!A:A,1,FALSE) -> JDA_PMM_CSP_REJECT_REP | I12: 1s
A13: CASE_PACK_EXPORT | B13: PMMDB | C13: apmmdb | D13: CSP_EXPORT | E13: JDA_PMM_CSP_REJECT_REP | F13: 22/12/2025 20:17:04 | G13: 22/12/2025 20:17:10 | H13: =VLOOKUP(E13,UAC!A:A,1,FALSE) -> JDA_PMM_CSP_REJECT_REP
A14: CASE_PACK_EXPORT | B14: PMMDB | C14: apmmdb | D14: CSP_EXPORT | E14: JDA_PMM_EXPORT_CHG_ALLOW | F14: 21/12/2025 19:59:08 | G14: 21/12/2025 19:59:16 | H14: =VLOOKUP(E14,UAC!A:A,1,FALSE) -> JDA_PMM_EXPORT_CHG_ALLOW | I14: 1s
A15: CASE_PACK_EXPORT | B15: PMMDB | C15: apmmdb | D15: CSP_EXPORT | E15: JDA_PMM_EXPORT_CHG_ALLOW | F15: 22/12/2025 20:16:09 | G15: 22/12/2025 20:16:17 | H15: =VLOOKUP(E15,UAC!A:A,1,FALSE) -> JDA_PMM_EXPORT_CHG_ALLOW
A16: CASE_PACK_EXPORT | B16: PMMDB | C16: apmmdb | D16: CSP_EXPORT | E16: T_CSP_EXPORT | F16: 21/12/2025 20:00:05 | G16: 21/12/2025 20:00:11 | H16: =VLOOKUP(E16,UAC!A:A,1,FALSE) -> #N/A | I16: 6s
A17: CASE_PACK_EXPORT | B17: PMMDB | C17: apmmdb | D17: CSP_EXPORT | E17: T_CSP_EXPORT | F17: 22/12/2025 20:17:10 | G17: 22/12/2025 20:17:16 | H17: =VLOOKUP(E17,UAC!A:A,1,FALSE) -> #N/A
A18: IMPORT_PRM_TO_PMM | B18: PMMDB | C18: apmmdb | D18: IMP_PRM_PMM | E18: H_IMP_PRM_TO_PROMO | F18: 21/12/2025 22:24:05 | G18: 21/12/2025 22:24:07 | H18: =VLOOKUP(E18,UAC!A:A,1,FALSE) -> #N/A | I18: 1s
A19: IMPORT_PRM_TO_PMM | B19: PMMDB | C19: apmmdb | D19: IMP_PRM_PMM | E19: H_IMP_PRM_TO_PROMO | F19: 22/12/2025 22:20:15 | G19: 22/12/2025 22:20:18 | H19: =VLOOKUP(E19,UAC!A:A,1,FALSE) -> #N/A
A20: IMPORT_PRM_TO_PMM | B20: PMMDB | C20: apmmdb | D20: IMP_PRM_PMM | E20: JDA_PMM_IMPORT_PO_ALLOCATION | F20: 21/12/2025 22:24:10 | G20: 21/12/2025 22:24:11 | H20: =VLOOKUP(E20,UAC!A:A,1,FALSE) -> JDA_PMM_IMPORT_PO_ALLOCATION | I20: 6s
A21: IMPORT_PRM_TO_PMM | B21: PMMDB | C21: apmmdb | D21: IMP_PRM_PMM | E21: JDA_PMM_IMPORT_PO_ALLOCATION | F21: 22/12/2025 22:20:20 | G21: 22/12/2025 22:20:21 | H21: =VLOOKUP(E21,UAC!A:A,1,FALSE) -> JDA_PMM_IMPORT_PO_ALLOCATION
A22: IMPORT_PRM_TO_PMM | B22: PMMDB | C22: apmmdb | D22: IMP_PRM_PMM | E22: JDA_PMM_IMPORT_PROMO | F22: 21/12/2025 22:24:08 | G22: 21/12/2025 22:24:09 | H22: =VLOOKUP(E22,UAC!A:A,1,FALSE) -> JDA_PMM_IMPORT_PROMO | I22: 31s
A23: IMPORT_PRM_TO_PMM | B23: PMMDB | C23: apmmdb | D23: IMP_PRM_PMM | E23: JDA_PMM_IMPORT_PROMO | F23: 22/12/2025 22:20:18 | G23: 22/12/2025 22:20:19 | H23: =VLOOKUP(E23,UAC!A:A,1,FALSE) -> JDA_PMM_IMPORT_PROMO
A24: IMPORT_PRM_TO_PMM | B24: PMMDB | C24: apmmdb | D24: IMP_PRM_PMM | E24: T_IMP_PRM_TO_PROMO | F24: 21/12/2025 22:24:12 | G24: 21/12/2025 22:24:14 | H24: =VLOOKUP(E24,UAC!A:A,1,FALSE) -> #N/A | I24: 1s
A25: IMPORT_PRM_TO_PMM | B25: PMMDB | C25: apmmdb | D25: IMP_PRM_PMM | E25: T_IMP_PRM_TO_PROMO | F25: 22/12/2025 22:20:21 | G25: 22/12/2025 22:20:23 | H25: =VLOOKUP(E25,UAC!A:A,1,FALSE) -> #N/A
A26: IMPORT_PROCS | B26: PMMDB | C26: apmmdb | D26: IMPORT_PROCS | E26: H_IMP_PROC | F26: 21/12/2025 19:00:58 | G26: 21/12/2025 19:01:00 | H26: =VLOOKUP(E26,UAC!A:A,1,FALSE) -> #N/A | I26: 6s
A27: IMPORT_PROCS | B27: PMMDB | C27: apmmdb | D27: IMPORT_PROCS | E27: H_IMP_PROC | F27: 22/12/2025 19:16:57 | G27: 22/12/2025 19:16:59 | H27: =VLOOKUP(E27,UAC!A:A,1,FALSE) -> #N/A
A28: IMPORT_PROCS | B28: PMMDB | C28: apmmdb | D28: IMPORT_PROCS | E28: JDA_PMM_IMPORT_PLANOGRAM | F28: 21/12/2025 19:01:10 | G28: 21/12/2025 19:25:24 | H28: =VLOOKUP(E28,UAC!A:A,1,FALSE) -> JDA_PMM_IMPORT_PLANOGRAM | I28: 31s
A29: IMPORT_PROCS | B29: PMMDB | C29: apmmdb | D29: IMPORT_PROCS | E29: JDA_PMM_IMPORT_PLANOGRAM | F29: 22/12/2025 19:17:17 | G29: 22/12/2025 19:37:11 | H29: =VLOOKUP(E29,UAC!A:A,1,FALSE) -> JDA_PMM_IMPORT_PLANOGRAM
A30: IMPORT_PROCS | B30: PMMDB | C30: apmmdb | D30: IMPORT_PROCS | E30: JDA_PMM_INT_NOTIFICATIONS | F30: 21/12/2025 19:01:00 | G30: 21/12/2025 19:01:10 | H30: =VLOOKUP(E30,UAC!A:A,1,FALSE) -> JDA_PMM_INT_NOTIFICATIONS | I30: 1s
A31: IMPORT_PROCS | B31: PMMDB | C31: apmmdb | D31: IMPORT_PROCS | E31: JDA_PMM_INT_NOTIFICATIONS | F31: 22/12/2025 19:17:00 | G31: 22/12/2025 19:17:17 | H31: =VLOOKUP(E31,UAC!A:A,1,FALSE) -> JDA_PMM_INT_NOTIFICATIONS
A32: IMPORT_PROCS | B32: PMMDB | C32: apmmdb | D32: IMPORT_PROCS | E32: T_IMP_PROC | F32: 21/12/2025 19:25:24 | G32: 21/12/2025 19:25:30 | H32: =VLOOKUP(E32,UAC!A:A,1,FALSE) -> #N/A | I32: 13s
A33: IMPORT_PROCS | B33: PMMDB | C33: apmmdb | D33: IMPORT_PROCS | E33: T_IMP_PROC | F33: 22/12/2025 19:37:11 | G33: 22/12/2025 19:37:17 | H33: =VLOOKUP(E33,UAC!A:A,1,FALSE) -> #N/A
A34: ITEM_EXPORT | B34: PMMDB | C34: apmmdb | D34: ITM_EXPORT | E34: H_ITM_EXPORT | F34: 21/12/2025 19:30:28 | G34: 21/12/2025 19:30:30 | H34: =VLOOKUP(E34,UAC!A:A,1,FALSE) -> #N/A | I34: 31s
A35: ITEM_EXPORT | B35: PMMDB | C35: apmmdb | D35: ITM_EXPORT | E35: H_ITM_EXPORT | F35: 22/12/2025 19:43:03 | G35: 22/12/2025 19:43:06 | H35: =VLOOKUP(E35,UAC!A:A,1,FALSE) -> #N/A
A36: ITEM_EXPORT | B36: PMMDB | C36: apmmdb | D36: ITM_EXPORT | E36: JDA_PMM_ITM_ATTR_MAINT | F36: 21/12/2025 19:41:06 | G36: 21/12/2025 19:58:17 | H36: =VLOOKUP(E36,UAC!A:A,1,FALSE) -> JDA_PMM_ITM_ATTR_MAINT | I36: 6s
A37: ITEM_EXPORT | B37: PMMDB | C37: apmmdb | D37: ITM_EXPORT | E37: JDA_PMM_ITM_ATTR_MAINT | F37: 22/12/2025 19:59:33 | G37: 22/12/2025 20:15:24 | H37: =VLOOKUP(E37,UAC!A:A,1,FALSE) -> JDA_PMM_ITM_ATTR_MAINT
A38: ITEM_EXPORT | B38: PMMDB | C38: apmmdb | D38: ITM_EXPORT | E38: JDA_PMM_ITM_EXPORT_ITEM_AF | F38: 21/12/2025 19:30:30 | G38: 21/12/2025 19:30:57 | H38: =VLOOKUP(E38,UAC!A:A,1,FALSE) -> JDA_PMM_ITM_EXPORT_ITEM_AF | I38: 6s
A39: ITEM_EXPORT | B39: PMMDB | C39: apmmdb | D39: ITM_EXPORT | E39: JDA_PMM_ITM_EXPORT_ITEM_AF | F39: 22/12/2025 19:43:06 | G39: 22/12/2025 19:43:50 | H39: =VLOOKUP(E39,UAC!A:A,1,FALSE) -> JDA_PMM_ITM_EXPORT_ITEM_AF
A40: ITEM_EXPORT | B40: PMMDB | C40: apmmdb | D40: ITM_EXPORT | E40: JDA_PMM_ITM_EXPORT_ITEM_ATTRIBUTE | F40: 21/12/2025 19:30:30 | G40: 21/12/2025 19:31:54 | H40: =VLOOKUP(E40,UAC!A:A,1,FALSE) -> JDA_PMM_ITM_EXPORT_ITEM_ATTRIBUTE | I40: 6s
...

Sheet UAC
A1: Task | B1: Task Type | C1: Workflow | D1: Launch Time | E1: task-time | F1: Compare DU
A2: MASTER_PMMDB | B2: Workflow | D2: 46013.792 | E2: 46013.792 | F2: =_xlfn.IFNA(VLOOKUP(A2,APMMDB!E:E,1,FALSE),VLOOKUP(LEFT(A2, FIND("♦", SUBSTITUTE(A2, "_", "♦", LEN(A2)-LEN(SUBSTITUTE(A2,"_","")))) - 1),APMMDB!D:D,1,FALSE)) -> #N/A
A3: JDA_PMM_COST_ELE_RETAIL_COMP_RPT | B3: Linux/Unix | C3: BUILD_COMP_REP_PMMDB | D3: 46013.792 | E3: 46013.792 | F3: =_xlfn.IFNA(VLOOKUP(A3,APMMDB!E:E,1,FALSE),VLOOKUP(LEFT(A3, FIND("♦", SUBSTITUTE(A3, "_", "♦", LEN(A3)-LEN(SUBSTITUTE(A3,"_","")))) - 1),APMMDB!D:D,1,FALSE)) -> #N/A
A4: JDA_PMM_DFU_DFUVIEW_PPARM_COMP | B4: Linux/Unix | C4: BUILD_COMP_REP_PMMDB | D4: 46013.792 | E4: 46013.792 | F4: =_xlfn.IFNA(VLOOKUP(A4,APMMDB!E:E,1,FALSE),VLOOKUP(LEFT(A4, FIND("♦", SUBSTITUTE(A4, "_", "♦", LEN(A4)-LEN(SUBSTITUTE(A4,"_","")))) - 1),APMMDB!D:D,1,FALSE)) -> #N/A
A5: JDA_PMM_CSP_EXPORT_CASEPACK | B5: Linux/Unix | C5: CSP_EXPORT_PMMDB | D5: 46013.792 | E5: 46013.792 | F5: =_xlfn.IFNA(VLOOKUP(A5,APMMDB!E:E,1,FALSE),VLOOKUP(LEFT(A5, FIND("♦", SUBSTITUTE(A5, "_", "♦", LEN(A5)-LEN(SUBSTITUTE(A5,"_","")))) - 1),APMMDB!D:D,1,FALSE)) -> JDA_PMM_CSP_EXPORT_CASEPACK
A6: JDA_PMM_CSP_EXPORT_CASEPACK_AF | B6: Linux/Unix | C6: CSP_EXPORT_PMMDB | D6: 46013.792 | E6: 46013.792 | F6: =_xlfn.IFNA(VLOOKUP(A6,APMMDB!E:E,1,FALSE),VLOOKUP(LEFT(A6, FIND("♦", SUBSTITUTE(A6, "_", "♦", LEN(A6)-LEN(SUBSTITUTE(A6,"_","")))) - 1),APMMDB!D:D,1,FALSE)) -> JDA_PMM_CSP_EXPORT_CASEPACK_AF
A7: JDA_PMM_CSP_EXPORT_CASEPACK_COST | B7: Linux/Unix | C7: CSP_EXPORT_PMMDB | D7: 46013.792 | E7: 46013.792 | F7: =_xlfn.IFNA(VLOOKUP(A7,APMMDB!E:E,1,FALSE),VLOOKUP(LEFT(A7, FIND("♦", SUBSTITUTE(A7, "_", "♦", LEN(A7)-LEN(SUBSTITUTE(A7,"_","")))) - 1),APMMDB!D:D,1,FALSE)) -> JDA_PMM_CSP_EXPORT_CASEPACK_COST
A8: JDA_PMM_CSP_EXPORT_CASEPACK_FLAT | B8: Linux/Unix | C8: CSP_EXPORT_PMMDB | D8: 46013.792 | E8: 46013.792 | F8: =_xlfn.IFNA(VLOOKUP(A8,APMMDB!E:E,1,FALSE),VLOOKUP(LEFT(A8, FIND("♦", SUBSTITUTE(A8, "_", "♦", LEN(A8)-LEN(SUBSTITUTE(A8,"_","")))) - 1),APMMDB!D:D,1,FALSE)) -> JDA_PMM_CSP_EXPORT_CASEPACK_FLAT
A9: JDA_PMM_CSP_REJECT_REP | B9: Linux/Unix | C9: CSP_EXPORT_PMMDB | D9: 46013.792 | E9: 46013.792 | F9: =_xlfn.IFNA(VLOOKUP(A9,APMMDB!E:E,1,FALSE),VLOOKUP(LEFT(A9, FIND("♦", SUBSTITUTE(A9, "_", "♦", LEN(A9)-LEN(SUBSTITUTE(A9,"_","")))) - 1),APMMDB!D:D,1,FALSE)) -> JDA_PMM_CSP_REJECT_REP
A10: JDA_PMM_EXPORT_CHG_ALLOW | B10: Linux/Unix | C10: CSP_EXPORT_PMMDB | D10: 46013.792 | E10: 46013.792 | F10: =_xlfn.IFNA(VLOOKUP(A10,APMMDB!E:E,1,FALSE),VLOOKUP(LEFT(A10, FIND("♦", SUBSTITUTE(A10, "_", "♦", LEN(A10)-LEN(SUBSTITUTE(A10,"_","")))) - 1),APMMDB!D:D,1,FALSE)) -> JDA_PMM_EXPORT_CHG_ALLOW
A11: JDA_PMM_IMPORT_PO_ALLOCATION | B11: Linux/Unix | C11: IMP_PRM_PMM_PMMDB | D11: 46013.792 | E11: 46013.792 | F11: =_xlfn.IFNA(VLOOKUP(A11,APMMDB!E:E,1,FALSE),VLOOKUP(LEFT(A11, FIND("♦", SUBSTITUTE(A11, "_", "♦", LEN(A11)-LEN(SUBSTITUTE(A11,"_","")))) - 1),APMMDB!D:D,1,FALSE)) -> JDA_PMM_IMPORT_PO_ALLOCATION
A12: JDA_PMM_IMPORT_PROMO | B12: Linux/Unix | C12: IMP_PRM_PMM_PMMDB | D12: 46013.792 | E12: 46013.792 | F12: =_xlfn.IFNA(VLOOKUP(A12,APMMDB!E:E,1,FALSE),VLOOKUP(LEFT(A12, FIND("♦", SUBSTITUTE(A12, "_", "♦", LEN(A12)-LEN(SUBSTITUTE(A12,"_","")))) - 1),APMMDB!D:D,1,FALSE)) -> JDA_PMM_IMPORT_PROMO
A13: JDA_PMM_IMPORT_PLANOGRAM | B13: Linux/Unix | C13: IMPORT_PROCS_PMMDB | D13: 46013.792 | E13: 46013.792 | F13: =_xlfn.IFNA(VLOOKUP(A13,APMMDB!E:E,1,FALSE),VLOOKUP(LEFT(A13, FIND("♦", SUBSTITUTE(A13, "_", "♦", LEN(A13)-LEN(SUBSTITUTE(A13,"_","")))) - 1),APMMDB!D:D,1,FALSE)) -> JDA_PMM_IMPORT_PLANOGRAM
A14: JDA_PMM_INT_NOTIFICATIONS | B14: Linux/Unix | C14: IMPORT_PROCS_PMMDB | D14: 46013.792 | E14: 46013.792 | F14: =_xlfn.IFNA(VLOOKUP(A14,APMMDB!E:E,1,FALSE),VLOOKUP(LEFT(A14, FIND("♦", SUBSTITUTE(A14, "_", "♦", LEN(A14)-LEN(SUBSTITUTE(A14,"_","")))) - 1),APMMDB!D:D,1,FALSE)) -> JDA_PMM_INT_NOTIFICATIONS
... A211: JDA_PMM_WIS_IMPORT_SDIPHYDTI | B211: Linux/Unix | C211: WIS_IMPORT_PMMDB | D211: 46013.792 | E211: 46013.792 | F211: =_xlfn.IFNA(VLOOKUP(A211,APMMDB!E:E,1,FALSE),VLOOKUP(LEFT(A211, FIND("♦", SUBSTITUTE(A211, "_", "♦", LEN(A211)-LEN(SUBSTITUTE(A211,"_","")))) - 1),APMMDB!D:D,1,FALSE)) -> JDA_PMM_WIS_IMPORT_SDIPHYDTI
